<?xml version="1.0"?>
<robot xmlns:xacro="http://www.ros.org/wiki/xacro"  >


    <material name="white">
        <color rgba="1 1 1 1" />
        
    </material>
    <material name="orange">
        <color rgba="1 0.3 0.1 1" />
        
    </material>
    <material name="blue">
        <color rgba="0.2 0.2 1 1" />
        
    </material>
    <material name="black">
        <color rgba="0 0 0 1" />
        
    </material>

<!-- base link -->
    <link name="base_link">

    </link>
<!-- chassis link -->
    <joint name="chassis_link" type="fixed">
        <parent link="base_link"/>
        <child link="chassis"/>
        <origin xyz="-0.1 0.0 0.0"/>
    </joint>
    <link name="chassis">
        <visual>
                <origin xyz="0.15 0.0 0.075"/>
                <geometry>
                    <box size="0.3 0.3 0.15"/>
                </geometry>
                <material name="white">
                    
                </material>
        </visual>
        
    </link>
    <!-- left wheel joint-->
    <joint name = "left_wheel_Joint" type ="continuous">
        <parent link="base_link"/>
        <child link="left_wheel"/>
        <origin xyz="0.0 0.175 0.0" rpy="-${pi/2} 0.0 0.0"/>
        <axis xyz="0.0 0.0 1"/>
    </joint>

    <link name="left_wheel">
        <!-- <inertial>
            <origin xyz="0.0 0.0 0.0" rpy="0.0 0.0 0.0"/>
            <mass value="0.0"/>
            <inertia ixx="0.0" ixy="0.0" ixz="0.0" iyy="0.0" iyz="0.0" izz="0.0"/>
        </inertial> -->
        <visual name="">
            <origin xyz="0.0 0.0 0.0" rpy="0.0 0.0 0.0"/>
            <geometry>
                <geometry>
                    <cylinder radius="0.05" length="0.04"/>
                </geometry>
            </geometry>
            <material name="white">
            </material>
        </visual>
        <!-- <collision>
            <origin xyz="0.0 0.0 0.0" rpy="0.0 0.0 0.0"/>
            <geometry>
                <box size="0.0 0.0 0.0"/>
            </geometry>
        </collision> -->
    </link>

    <!-- right wheel joint-->
    <joint name = "right_wheel_Joint" type ="continuous">
        <parent link="base_link"/>
        <child link="right_wheel"/>
        <origin xyz="0.0 -0.175 0.0" rpy="-${pi/2} 0.0 0.0"/>
        <axis xyz="0.0 0.0 -1"/>
    </joint>

    <link name="right_wheel">
        <!-- <inertial>
            <origin xyz="0.0 0.0 0.0" rpy="0.0 0.0 0.0"/>
            <mass value="0.0"/>
            <inertia ixx="0.0" ixy="0.0" ixz="0.0" iyy="0.0" iyz="0.0" izz="0.0"/>
        </inertial> -->
        <visual name="">
            <origin xyz="0.0 0.0 0.0" rpy="0.0 0.0 0.0"/>
            <geometry>
                <geometry>
                    <cylinder radius="0.05" length="0.04"/>
                </geometry>
            </geometry>
            <material name="white">
            </material>

        </visual>
        <!-- <collision>
            <origin xyz="0.0 0.0 0.0" rpy="0.0 0.0 0.0"/>
            <geometry>
                <box size="0.0 0.0 0.0"/>
            </geometry>
        </collision> -->
    </link>
        
</robot>