<?xml version="1.0"?>
<robot xmlns:xacro="http://www.ros.org/wiki/xacro"  >

    <xacro:include filename="inertial_macros.xacro"/>
    <material name="white">
        <color rgba="1 1 1 1" />
        
    </material>

    <material name="orange">
        <color rgba="1 0.3 0.1 1" />
        
    </material>
    
    <material name="blue">
        <color rgba="0.2 0.2 1 1" />
        
    </material>

    <material name="black">
        <color rgba="0 0 0 1" />
        
    </material>

    <material name="red">
        <color rgba="1 0 0 1" />
        
    </material>

<!-- base link -->
    <link name="base_link">

    </link>

    <!-- Base footprint link -->

<joint name="base_footprint_joint" type="fixed">
    <origin xyz="0.0 0.0 0.0" rpy="0.0 0.0 0.0"/>
    <parent link="base_link"/>
    <child link="base_footprint"/>
    <axis xyz="0.0 0.0 0.0"/>
    <limit lower="0.0" upper="0.0" effort="0.0" velocity="0.0"/>
</joint>

<link name="base_footprint">
    
</link>
<!-- chassis link -->
    <joint name="chassis_link" type="fixed">
        <parent link="base_link"/>
        <child link="chassis"/>
        <origin xyz="-0.1 0.0 0.0"/>
    </joint>
    <link name="chassis">
        <visual>
                <origin xyz="0.15 0.0 0.075"/>
                <geometry>
                    <box size="0.3 0.3 0.15"/>
                </geometry>
                <material name="white">
                    
                </material>
        </visual>
        <collision>
                <origin xyz="0.15 0.0 0.075"/>
                <geometry>
                    <box size="0.3 0.3 0.15"/>
                </geometry>
                
        </collision>
        <xacro:inertial_box mass="0.5" x="0.3" y="0.3" z="0.15">
            <origin xyz="0.15 0 0.075" rpy="0.0 0.0 0.0"/>
        </xacro:inertial_box>
        
    </link>
    <gazebo reference="chassis">
        <material>
            Gazebo/White
        </material>
    </gazebo>
    <!-- left wheel joint-->
    <joint name = "left_wheel_Joint" type ="continuous">
        <parent link="base_link"/>
        <child link="left_wheel"/>
        <origin xyz="0.0 0.175 0.0" rpy="-${pi/2} 0.0 0.0"/>
        <axis xyz="0.0 0.0 1"/>
    </joint>

    <link name="left_wheel">
        <!-- <inertial>
            <origin xyz="0.0 0.0 0.0" rpy="0.0 0.0 0.0"/>
            <mass value="0.0"/>
            <inertia ixx="0.0" ixy="0.0" ixz="0.0" iyy="0.0" iyz="0.0" izz="0.0"/>
        </inertial> -->
        <visual name="">
            <origin xyz="0.0 0.0 0.0" rpy="0.0 0.0 0.0"/>
            <geometry>
                
                <cylinder radius="0.05" length="0.04"/>
                
            </geometry>
            <material name="blue"/>
        </visual>
        <collision>
            <origin xyz="0.0 0.0 0.0" rpy="0.0 0.0 0.0"/>
            <geometry>
                
                <cylinder radius="0.05" length="0.04"/>
                
            </geometry>
        </collision>
        <xacro:inertial_cylinder mass="0.1" length="0.04" radius="0.05">
            <origin xyz="0.0 0.0 0.0" rpy="0.0 0.0 0.0"/>
        </xacro:inertial_cylinder>
    </link>
    <gazebo reference="left_wheel">
        <material>
            Gazebo/Blue
        </material>
    </gazebo>

    <!-- right wheel joint-->
    
    <joint name = "right_wheel_Joint" type ="continuous">
        <parent link="base_link"/>
        <child link="right_wheel"/>
        <origin xyz="0.0 -0.175 0.0" rpy="-${pi/2} 0.0 0.0"/>
        <axis xyz="0.0 0.0 -1"/>
    </joint>

    <link name="right_wheel">
        <visual>
            <origin xyz="0.0 0.0 0.0" rpy="0.0 0.0 0.0"/>
            <geometry>
                    <cylinder radius="0.05" length="0.04"/>
            </geometry>
            <material name="blue"/>

        </visual>
        <collision>
            <origin xyz="0.0 0.0 0.0" rpy="0.0 0.0 0.0"/>
            <geometry>
                    <cylinder radius="0.05" length="0.04"/>
            </geometry>

        </collision>
        <xacro:inertial_cylinder mass="0.1" length="0.04" radius="0.05">
            <origin xyz="0.0 0.0 0.0" rpy="0.0 0.0 0.0"/>
        </xacro:inertial_cylinder>
    </link>
   
    <gazebo reference="right_wheel">
        <material>
            Gazebo/Blue
        </material>
    </gazebo>

    <!-- CASTER WHEEL LINK -->
    
    <joint name="caster_wheel_joint" type="fixed">
        
        <parent link="chassis"/>
        <child link="caster_wheel"/>
        <origin xyz="0.24 0.0 0.0"/>
    </joint>

    <link name="caster_wheel">
       
        <visual>
            <geometry>
                <sphere radius="0.05"/>
            </geometry>
            <material name="back">
            </material>
        </visual>
        <collision>
            <geometry>
                <sphere radius="0.05"/>
            </geometry>
        </collision>
        <xacro:inertial_sphere mass="0.1" radius="0.05">
            <origin xyz="0.0 0.0 0.0" rpy="0.0 0.0 0.0"/>
        </xacro:inertial_sphere>
    </link>

    <gazebo reference="caster_wheel">
        <material>
            Gazebo/Black
        </material>
        <mu1 value="0.001"/>
        <mu2 value="0.002"/>
    </gazebo>

</robot>